Workbook

Sheet Sheet1
A1: 商品內部圖片 | B1: 廠商編號 | C1: 商品編號 | D1: 款號 | E1: 採購流水號 | F1: 單據日期 | G1: 採購貨號 | H1: 尺寸 | I1: 顏色 | J1: 顏色名稱 | K1: 是否主色 | L1: 商品名稱 | M1: 年度 | N1: 季節 | O1: 商品週數 | P1: 週數日期 | Q1: 續賣週數 | R1: 最新上架日期 | S1: 預定到貨日 | T1: 品牌 | U1: 商品大分類 | V1: 商品中分類 | W1: 台幣_售價 | X1: 美金_售價 | Y1: 馬幣_售價 | Z1: 越南盾_售價 | AA1: 總售價台幣 | AB1: 重量(克) | AC1: 採購單號 | AD1: 採購類別 | AE1: 色數 | AF1: MY_1(官網)頭單 | AG1: MY_A(門市)頭單 | AH1: MY_Z(ZALORA)頭單 | AI1: TW_1(官網)頭單 | AJ1: TW_A(門市)頭單 | AK1: 數量 | AL1: 總頭單量加總 | AM1: 一驗數量 | AN1: 二驗數量 | AO1: 總驗數量 | AP1: 是否結單 | AQ1: 結單日期 | AR1: MY_A(門市)級別 | AS1: MY_1(官網)級別 | AT1: TW_A(門市)級別 | AU1: TW_1(官網)級別 | AV1: 特別要求 | AW1: 是否企劃款 | AX1: 備註 | AY1: 商品成分 | AZ1: 彈性 | BA1: 版型 | BB1: 厚度 | BC1: 觸感 | BD1: 商品條碼 | BE1: 小白單編號 | BF1: 領標 | BG1: 品項 | BH1: 預購款
A2: https://airsblobstage.blob.core.windows.net/photo/purchasephoto/SH3626QT.webp | B2: SH | C2: 2541826022 | D2: SH3626QT | E2: 252-3626QT | F2: 20260105 | G2: 3626QT | H2: F | I2: 006 | J2: 杏 | K2: N | L2: 水手領排扣長袖針織外套 | M2: 26 | N2: 冬 | O2: W2 | P2: 2026-01-05 | S2: 20260119 | T2: OL | U2: 外套 | V2: 寬鬆外套 | W2: 1580 | X2: 64.99 | Y2: 209 | Z2: 1139000 | AA2: 869000 | AB2: 0 | AD2: Outlet追加單 | AE2: 2 | AJ2: 250 | AK2: 250 | AL2: 550 | AM2: 249 | AN2: 0 | AO2: 249 | AP2: Y | AQ2: 20260119 | AV2: 洗滌注意： ※ 首次洗滌時,深色/飽和色系 較易釋出多餘的固色劑, 屬於正常現象。 ※ 深色衣物建議在首次穿著前先下水清洗, 有助釋出多餘染劑，減少掉色或移染, 可降低染色風險。 ※ 深色與淺色衣物請分開洗滌，避免互相染色或產生移染現象。 ※ 穿搭時請避免與淺色衣物、配件、飾品一同搭配使用，以防止因摩擦或潮濕而導致染色。 | AW2: N | AX2: 3號袋、襯紙 | AY2: 主紗:亞克力纖維50%尼龍27%聚酯纖維13% 尺寸:F | BD2: 2541826022006004 | BE2: R260105021 | BF2: B | BG2: 毛織 | BH2: =IF(COUNTIF(工作表1!A:A, $C2)>0, "預購款", "非預購款") -> 非預購款
A3: https://airsblobstage.blob.core.windows.net/photo/purchasephoto/SH3626QT.webp | B3: SH | C3: 2541826022 | D3: SH3626QT | E3: 252-3626QT | F3: 20260105 | G3: 3626QT | H3: F | I3: 996 | J3: 淺藍 | K3: N | L3: 水手領排扣長袖針織外套 | M3: 26 | N3: 冬 | O3: W2 | P3: 2026-01-05 | S3: 20260119 | T3: OL | U3: 外套 | V3: 寬鬆外套 | W3: 1580 | X3: 64.99 | Y3: 209 | Z3: 1139000 | AA3: 869000 | AB3: 0 | AD3: Outlet追加單 | AE3: 2 | AJ3: 300 | AK3: 300 | AL3: 550 | AM3: 300 | AN3: 0 | AO3: 300 | AP3: Y | AQ3: 20260119 | AV3: 洗滌注意： ※ 首次洗滌時,深色/飽和色系 較易釋出多餘的固色劑, 屬於正常現象。 ※ 深色衣物建議在首次穿著前先下水清洗, 有助釋出多餘染劑，減少掉色或移染, 可降低染色風險。 ※ 深色與淺色衣物請分開洗滌，避免互相染色或產生移染現象。 ※ 穿搭時請避免與淺色衣物、配件、飾品一同搭配使用，以防止因摩擦或潮濕而導致染色。 | AW3: N | AX3: 3號袋、襯紙 | AY3: 主紗:亞克力纖維50%尼龍27%聚酯纖維13% 尺寸:F | BD3: 2541826022996004 | BE3: R260105021 | BF3: B | BG3: 毛織 | BH3: =IF(COUNTIF(工作表1!A:A, $C3)>0, "預購款", "非預購款") -> 非預購款
A4: https://airsblobstage.blob.core.windows.net/photo/purchasephoto/SH188 1QT.webp | B4: SH | C4: 2611821026 | D4: SH188-1QT | E4: 252-188-1QT | F4: 20260304 | G4: 188-1QT | H4: F | I4: 002 | J4: 白 | K4: N | L4: 長袖襯衫 | M4: 26 | N4: 春 | O4: W10 | P4: 2026-03-02 | S4: 20260318 | T4: OL | U4: 上衣 | V4: 長袖襯衫 | W4: 1180 | X4: 49.99 | Y4: 155 | Z4: 859000 | AA4: 472000 | AB4: 0 | AD4: Outlet追加單 | AE4: 2 | AJ4: 200 | AK4: 200 | AL4: 400 | AM4: 200 | AN4: 0 | AO4: 200 | AP4: Y | AQ4: 20260312 | AV4: 洗滌注意： ※ 首次洗滌時,深色/飽和色系 較易釋出多餘的固色劑, 屬於正常現象。 ※ 深色衣物建議在首次穿著前先下水清洗, 有助釋出多餘染劑，減少掉色或移染, 可降低染色風險。 ※ 深色與淺色衣物請分開洗滌，避免互相染色或產生移染現象。 ※ 穿搭時請避免與淺色衣物、配件、飾品一同搭配使用，以防止因摩擦或潮濕而導致染色。 | AW4: N | AX4: 2號袋、襯紙、領標*2、洗標*2、成分標*2 | AY4: 表布:棉100% 外件表布:嫘縈50%聚酯纖維28%尼龍22% 尺寸:F | BD4: 2611821026002004 | BE4: R260304086 | BF4: B | BG4: 平織 | BH4: =IF(COUNTIF(工作表1!A:A, $C4)>0, "預購款", "非預購款") -> 非預購款
A5: https://airsblobstage.blob.core.windows.net/photo/purchasephoto/SH188 1QT.webp | B5: SH | C5: 2611821026 | D5: SH188-1QT | E5: 252-188-1QT | F5: 20260304 | G5: 188-1QT | H5: F | I5: 003 | J5: 藍 | K5: N | L5: 長袖襯衫 | M5: 26 | N5: 春 | O5: W10 | P5: 2026-03-02 | S5: 20260318 | T5: OL | U5: 上衣 | V5: 長袖襯衫 | W5: 1180 | X5: 49.99 | Y5: 155 | Z5: 859000 | AA5: 472000 | AB5: 0 | AD5: Outlet追加單 | AE5: 2 | AJ5: 200 | AK5: 200 | AL5: 400 | AM5: 200 | AN5: 0 | AO5: 200 | AP5: Y | AQ5: 20260312 | AV5: 洗滌注意： ※ 首次洗滌時,深色/飽和色系 較易釋出多餘的固色劑, 屬於正常現象。 ※ 深色衣物建議在首次穿著前先下水清洗, 有助釋出多餘染劑，減少掉色或移染, 可降低染色風險。 ※ 深色與淺色衣物請分開洗滌，避免互相染色或產生移染現象。 ※ 穿搭時請避免與淺色衣物、配件、飾品一同搭配使用，以防止因摩擦或潮濕而導致染色。 | AW5: N | AX5: 2號袋、襯紙、領標*2、洗標*2、成分標*2 | AY5: 表布:棉100% 外件表布:嫘縈50%聚酯纖維28%尼龍22% 尺寸:F | BD5: 2611821026003004 | BE5: R260304086 | BF5: B | BG5: 平織 | BH5: =IF(COUNTIF(工作表1!A:A, $C5)>0, "預購款", "非預購款") -> 非預購款
A6: https://airsblobstage.blob.core.windows.net/photo/purchasephoto/SH60037QT.webp | B6: SH | C6: 2611834002 | D6: SH60037QT | E6: 252-60037QT | F6: 20260304 | G6: 60037QT | H6: S | I6: 001 | J6: 黑 | K6: N | L6: 側開衩短褲裙 | M6: 26 | N6: 春 | O6: W10 | P6: 2026-03-02 | S6: 20260318 | T6: OL | U6: 褲裙 | V6: 短褲 | W6: 1080 | X6: 44.99 | Y6: 139 | Z6: 779000 | AA6: 486000 | AB6: 0 | AD6: Outlet追加單 | AE6: 2 | AJ6: 80 | AK6: 80 | AL6: 450 | AM6: 80 | AN6: 0 | AO6: 80 | AP6: Y | AQ6: 20260320 | AV6: 洗滌注意： ※ 首次洗滌時,深色/飽和色系 較易釋出多餘的固色劑, 屬於正常現象。 ※ 深色衣物建議在首次穿著前先下水清洗, 有助釋出多餘染劑，減少掉色或移染, 可降低染色風險。 ※ 深色與淺色衣物請分開洗滌，避免互相染色或產生移染現象。 ※ 穿搭時請避免與淺色衣物、配件、飾品一同搭配使用，以防止因摩擦或潮濕而導致染色。 | AW6: N | AX6: 2號袋、襯紙 | AY6: 表布:聚酯纖維96%彈性纖維4% 裡布:聚酯纖維100% 尺寸:S.M.L | BD6: 2611834002001001 | BE6: R260304087 | BF6: B | BG6: 平織 | BH6: =IF(COUNTIF(工作表1!A:A, $C6)>0, "預購款", "非預購款") -> 非預購款
A7: https://airsblobstage.blob.core.windows.net/photo/purchasephoto/SH60037QT.webp | B7: SH | C7: 2611834002 | D7: SH60037QT | E7: 252-60037QT | F7: 20260304 | G7: 60037QT | H7: M | I7: 001 | J7: 黑 | K7: N | L7: 側開衩短褲裙 | M7: 26 | N7: 春 | O7: W10 | P7: 2026-03-02 | S7: 20260318 | T7: OL | U7: 褲裙 | V7: 短褲 | W7: 1080 | X7: 44.99 | Y7: 139 | Z7: 779000 | AA7: 486000 | AB7: 0 | AD7: Outlet追加單 | AE7: 2 | AJ7: 80 | AK7: 80 | AL7: 450 | AM7: 80 | AN7: 0 | AO7: 80 | AP7: Y | AQ7: 20260320 | AV7: 洗滌注意： ※ 首次洗滌時,深色/飽和色系 較易釋出多餘的固色劑, 屬於正常現象。 ※ 深色衣物建議在首次穿著前先下水清洗, 有助釋出多餘染劑，減少掉色或移染, 可降低染色風險。 ※ 深色與淺色衣物請分開洗滌，避免互相染色或產生移染現象。 ※ 穿搭時請避免與淺色衣物、配件、飾品一同搭配使用，以防止因摩擦或潮濕而導致染色。 | AW7: N | AX7: 2號袋、襯紙 | AY7: 表布:聚酯纖維96%彈性纖維4% 裡布:聚酯纖維100% 尺寸:S.M.L | BD7: 2611834002001002 | BE7: R260304087 | BF7: B | BG7: 平織 | BH7: =IF(COUNTIF(工作表1!A:A, $C7)>0, "預購款", "非預購款") -> 非預購款
A8: https://airsblobstage.blob.core.windows.net/photo/purchasephoto/SH60037QT.webp | B8: SH | C8: 2611834002 | D8: SH60037QT | E8: 252-60037QT | F8: 20260304 | G8: 60037QT | H8: L | I8: 001 | J8: 黑 | K8: N | L8: 側開衩短褲裙 | M8: 26 | N8: 春 | O8: W10 | P8: 2026-03-02 | S8: 20260318 | T8: OL | U8: 褲裙 | V8: 短褲 | W8: 1080 | X8: 44.99 | Y8: 139 | Z8: 779000 | AA8: 486000 | AB8: 0 | AD8: Outlet追加單 | AE8: 2 | AJ8: 60 | AK8: 60 | AL8: 450 | AM8: 60 | AN8: 0 | AO8: 60 | AP8: Y | AQ8: 20260320 | AV8: 洗滌注意： ※ 首次洗滌時,深色/飽和色系 較易釋出多餘的固色劑, 屬於正常現象。 ※ 深色衣物建議在首次穿著前先下水清洗, 有助釋出多餘染劑，減少掉色或移染, 可降低染色風險。 ※ 深色與淺色衣物請分開洗滌，避免互相染色或產生移染現象。 ※ 穿搭時請避免與淺色衣物、配件、飾品一同搭配使用，以防止因摩擦或潮濕而導致染色。 | AW8: N | AX8: 2號袋、襯紙 | AY8: 表布:聚酯纖維96%彈性纖維4% 裡布:聚酯纖維100% 尺寸:S.M.L | BD8: 2611834002001003 | BE8: R260304087 | BF8: B | BG8: 平織 | BH8: =IF(COUNTIF(工作表1!A:A, $C8)>0, "預購款", "非預購款") -> 非預購款
A9: https://airsblobstage.blob.core.windows.net/photo/purchasephoto/SH60037QT.webp | B9: SH | C9: 2611834002 | D9: SH60037QT | E9: 252-60037QT | F9: 20260304 | G9: 60037QT | H9: S | I9: 210 | J9: 深灰 | K9: N | L9: 側開衩短褲裙 | M9: 26 | N9: 春 | O9: W10 | P9: 2026-03-02 | S9: 20260318 | T9: OL | U9: 褲裙 | V9: 短褲 | W9: 1080 | X9: 44.99 | Y9: 139 | Z9: 779000 | AA9: 486000 | AB9: 0 | AD9: Outlet追加單 | AE9: 2 | AJ9: 80 | AK9: 80 | AL9: 450 | AM9: 80 | AN9: 0 | AO9: 80 | AP9: Y | AQ9: 20260320 | AV9: 洗滌注意： ※ 首次洗滌時,深色/飽和色系 較易釋出多餘的固色劑, 屬於正常現象。 ※ 深色衣物建議在首次穿著前先下水清洗, 有助釋出多餘染劑，減少掉色或移染, 可降低染色風險。 ※ 深色與淺色衣物請分開洗滌，避免互相染色或產生移染現象。 ※ 穿搭時請避免與淺色衣物、配件、飾品一同搭配使用，以防止因摩擦或潮濕而導致染色。 | AW9: N | AX9: 2號袋、襯紙 | AY9: 表布:聚酯纖維96%彈性纖維4% 裡布:聚酯纖維100% 尺寸:S.M.L | BD9: 2611834002210001 | BE9: R260304087 | BF9: B | BG9: 平織 | BH9: =IF(COUNTIF(工作表1!A:A, $C9)>0, "預購款", "非預購款") -> 非預購款
A10: https://airsblobstage.blob.core.windows.net/photo/purchasephoto/SH60037QT.webp | B10: SH | C10: 2611834002 | D10: SH60037QT | E10: 252-60037QT | F10: 20260304 | G10: 60037QT | H10: M | I10: 210 | J10: 深灰 | K10: N | L10: 側開衩短褲裙 | M10: 26 | N10: 春 | O10: W10 | P10: 2026-03-02 | S10: 20260318 | T10: OL | U10: 褲裙 | V10: 短褲 | W10: 1080 | X10: 44.99 | Y10: 139 | Z10: 779000 | AA10: 486000 | AB10: 0 | AD10: Outlet追加單 | AE10: 2 | AJ10: 100 | AK10: 100 | AL10: 450 | AM10: 100 | AN10: 0 | AO10: 100 | AP10: Y | AQ10: 20260320 | AV10: 洗滌注意： ※ 首次洗滌時,深色/飽和色系 較易釋出多餘的固色劑, 屬於正常現象。 ※ 深色衣物建議在首次穿著前先下水清洗, 有助釋出多餘染劑，減少掉色或移染, 可降低染色風險。 ※ 深色與淺色衣物請分開洗滌，避免互相染色或產生移染現象。 ※ 穿搭時請避免與淺色衣物、配件、飾品一同搭配使用，以防止因摩擦或潮濕而導致染色。 | AW10: N | AX10: 2號袋、襯紙 | AY10: 表布:聚酯纖維96%彈性纖維4% 裡布:聚酯纖維100% 尺寸:S.M.L | BD10: 2611834002210002 | BE10: R260304087 | BF10: B | BG10: 平織 | BH10: =IF(COUNTIF(工作表1!A:A, $C10)>0, "預購款", "非預購款") -> 非預購款
A11: https://airsblobstage.blob.core.windows.net/photo/purchasephoto/SH60037QT.webp | B11: SH | C11: 2611834002 | D11: SH60037QT | E11: 252-60037QT | F11: 20260304 | G11: 60037QT | H11: L | I11: 210 | J11: 深灰 | K11: N | L11: 側開衩短褲裙 | M11: 26 | N11: 春 | O11: W10 | P11: 2026-03-02 | S11: 20260318 | T11: OL | U11: 褲裙 | V11: 短褲 | W11: 1080 | X11: 44.99 | Y11: 139 | Z11: 779000 | AA11: 486000 | AB11: 0 | AD11: Outlet追加單 | AE11: 2 | AJ11: 50 | AK11: 50 | AL11: 450 | AM11: 50 | AN11: 0 | AO11: 50 | AP11: Y | AQ11: 20260320 | AV11: 洗滌注意： ※ 首次洗滌時,深色/飽和色系 較易釋出多餘的固色劑, 屬於正常現象。 ※ 深色衣物建議在首次穿著前先下水清洗, 有助釋出多餘染劑，減少掉色或移染, 可降低染色風險。 ※ 深色與淺色衣物請分開洗滌，避免互相染色或產生移染現象。 ※ 穿搭時請避免與淺色衣物、配件、飾品一同搭配使用，以防止因摩擦或潮濕而導致染色。 | AW11: N | AX11: 2號袋、襯紙 | AY11: 表布:聚酯纖維96%彈性纖維4% 裡布:聚酯纖維100% 尺寸:S.M.L | BD11: 2611834002210003 | BE11: R260304087 | BF11: B | BG11: 平織 | BH11: =IF(COUNTIF(工作表1!A:A, $C11)>0, "預購款", "非預購款") -> 非預購款
B12: SH | C12: 2611822011 | D12: SH2581QT | E12: 252-2581QT | F12: 20260311 | G12: 2581QT | H12: S | I12: 001 | J12: 黑 | K12: N | L12: 長裙 | M12: 26 | N12: 春 | O12: W10 | P12: 2026-03-02 | S12: 20260325 | T12: OL | U12: 裙子 | V12: 長裙 | W12: 1380 | X12: 54.99 | Y12: 179 | Z12: 989000 | AA12: 248400 | AB12: 0 | AD12: Outlet追加單 | AE12: 2 | AJ12: 45 | AK12: 45 | AL12: 180 | AM12: 47 | AN12: 0 | AO12: 47 | AP12: Y | AQ12: 20260320 | AV12: 洗滌注意： ※ 首次洗滌時,深色/飽和色系 較易釋出多餘的固色劑, 屬於正常現象。 ※ 深色衣物建議在首次穿著前先下水清洗, 有助釋出多餘染劑，減少掉色或移染, 可降低染色風險。 ※ 深色與淺色衣物請分開洗滌，避免互相染色或產生移染現象。 ※ 穿搭時請避免與淺色衣物、配件、飾品一同搭配使用，以防止因摩擦或潮濕而導致染色。 | AW12: N | AX12: 2號袋、襯紙 | AY12: 表布:嫘縈50%聚酯纖維45%彈性纖維5% 尺寸:S.M.L | BD12: 2611822011001001 | BE12: R260311036 | BF12: B | BG12: 針織 | BH12: =IF(COUNTIF(工作表1!A:A, $C12)>0, "預購款", "非預購款") -> 非預購款
B13: SH | C13: 2611822011 | D13: SH2581QT | E13: 252-2581QT | F13: 20260311 | G13: 2581QT | H13: M | I13: 001 | J13: 黑 | K13: N | L13: 長裙 | M13: 26 | N13: 春 | O13: W10 | P13: 2026-03-02 | S13: 20260325 | T13: OL | U13: 裙子 | V13: 長裙 | W13: 1380 | X13: 54.99 | Y13: 179 | Z13: 989000 | AA13: 248400 | AB13: 0 | AD13: Outlet追加單 | AE13: 2 | AJ13: 30 | AK13: 30 | AL13: 180 | AM13: 32 | AN13: 0 | AO13: 32 | AP13: Y | AQ13: 20260320 | AV13: 洗滌注意： ※ 首次洗滌時,深色/飽和色系 較易釋出多餘的固色劑, 屬於正常現象。 ※ 深色衣物建議在首次穿著前先下水清洗, 有助釋出多餘染劑，減少掉色或移染, 可降低染色風險。 ※ 深色與淺色衣物請分開洗滌，避免互相染色或產生移染現象。 ※ 穿搭時請避免與淺色衣物、配件、飾品一同搭配使用，以防止因摩擦或潮濕而導致染色。 | AW13: N | AX13: 2號袋、襯紙 | AY13: 表布:嫘縈50%聚酯纖維45%彈性纖維5% 尺寸:S.M.L | BD13: 2611822011001002 | BE13: R260311036 | BF13: B | BG13: 針織 | BH13: =IF(COUNTIF(工作表1!A:A, $C13)>0, "預購款", "非預購款") -> 非預購款
B14: SH | C14: 2611822011 | D14: SH2581QT | E14: 252-2581QT | F14: 20260311 | G14: 2581QT | H14: L | I14: 001 | J14: 黑 | K14: N | L14: 長裙 | M14: 26 | N14: 春 | O14: W10 | P14: 2026-03-02 | S14: 20260325 | T14: OL | U14: 裙子 | V14: 長裙 | W14: 1380 | X14: 54.99 | Y14: 179 | Z14: 989000 | AA14: 248400 | AB14: 0 | AD14: Outlet追加單 | AE14: 2 | AJ14: 15 | AK14: 15 | AL14: 180 | AM14: 15 | AN14: 0 | AO14: 15 | AP14: Y | AQ14: 20260320 | AV14: 洗滌注意： ※ 首次洗滌時,深色/飽和色系 較易釋出多餘的固色劑, 屬於正常現象。 ※ 深色衣物建議在首次穿著前先下水清洗, 有助釋出多餘染劑，減少掉色或移染, 可降低染色風險。 ※ 深色與淺色衣物請分開洗滌，避免互相染色或產生移染現象。 ※ 穿搭時請避免與淺色衣物、配件、飾品一同搭配使用，以防止因摩擦或潮濕而導致染色。 | AW14: N | AX14: 2號袋、襯紙 | AY14: 表布:嫘縈50%聚酯纖維45%彈性纖維5% 尺寸:S.M.L | BD14: 2611822011001003 | BE14: R260311036 | BF14: B | BG14: 針織 | BH14: =IF(COUNTIF(工作表1!A:A, $C14)>0, "預購款", "非預購款") -> 非預購款
B15: SH | C15: 2611822011 | D15: SH2581QT | E15: 252-2581QT | F15: 20260311 | G15: 2581QT | H15: S | I15: 210 | J15: 深灰 | K15: N | L15: 長裙 | M15: 26 | N15: 春 | O15: W10 | P15: 2026-03-02 | S15: 20260325 | T15: OL | U15: 裙子 | V15: 長裙 | W15: 1380 | X15: 54.99 | Y15: 179 | Z15: 989000 | AA15: 248400 | AB15: 0 | AD15: Outlet追加單 | AE15: 2 | AJ15: 45 | AK15: 45 | AL15: 180 | AM15: 47 | AN15: 0 | AO15: 47 | AP15: Y | AQ15: 20260320 | AV15: 洗滌注意： ※ 首次洗滌時,深色/飽和色系 較易釋出多餘的固色劑, 屬於正常現象。 ※ 深色衣物建議在首次穿著前先下水清洗, 有助釋出多餘染劑，減少掉色或移染, 可降低染色風險。 ※ 深色與淺色衣物請分開洗滌，避免互相染色或產生移染現象。 ※ 穿搭時請避免與淺色衣物、配件、飾品一同搭配使用，以防止因摩擦或潮濕而導致染色。 | AW15: N | AX15: 2號袋、襯紙 | AY15: 表布:嫘縈50%聚酯纖維45%彈性纖維5% 尺寸:S.M.L | BD15: 2611822011210001 | BE15: R260311036 | BF15: B | BG15: 針織 | BH15: =IF(COUNTIF(工作表1!A:A, $C15)>0, "預購款", "非預購款") -> 非預購款
B16: SH | C16: 2611822011 | D16: SH2581QT | E16: 252-2581QT | F16: 20260311 | G16: 2581QT | H16: M | I16: 210 | J16: 深灰 | K16: N | L16: 長裙 | M16: 26 | N16: 春 | O16: W10 | P16: 2026-03-02 | S16: 20260325 | T16: OL | U16: 裙子 | V16: 長裙 | W16: 1380 | X16: 54.99 | Y16: 179 | Z16: 989000 | AA16: 248400 | AB16: 0 | AD16: Outlet追加單 | AE16: 2 | AJ16: 30 | AK16: 30 | AL16: 180 | AM16: 31 | AN16: 0 | AO16: 31 | AP16: Y | AQ16: 20260320 | AV16: 洗滌注意： ※ 首次洗滌時,深色/飽和色系 較易釋出多餘的固色劑, 屬於正常現象。 ※ 深色衣物建議在首次穿著前先下水清洗, 有助釋出多餘染劑，減少掉色或移染, 可降低染色風險。 ※ 深色與淺色衣物請分開洗滌，避免互相染色或產生移染現象。 ※ 穿搭時請避免與淺色衣物、配件、飾品一同搭配使用，以防止因摩擦或潮濕而導致染色。 | AW16: N | AX16: 2號袋、襯紙 | AY16: 表布:嫘縈50%聚酯纖維45%彈性纖維5% 尺寸:S.M.L | BD16: 2611822011210002 | BE16: R260311036 | BF16: B | BG16: 針織 | BH16: =IF(COUNTIF(工作表1!A:A, $C16)>0, "預購款", "非預購款") -> 非預購款
B17: SH | C17: 2611822011 | D17: SH2581QT | E17: 252-2581QT | F17: 20260311 | G17: 2581QT | H17: L | I17: 210 | J17: 深灰 | K17: N | L17: 長裙 | M17: 26 | N17: 春 | O17: W10 | P17: 2026-03-02 | S17: 20260325 | T17: OL | U17: 裙子 | V17: 長裙 | W17: 1380 | X17: 54.99 | Y17: 179 | Z17: 989000 | AA17: 248400 | AB17: 0 | AD17: Outlet追加單 | AE17: 2 | AJ17: 15 | AK17: 15 | AL17: 180 | AM17: 16 | AN17: 0 | AO17: 16 | AP17: Y | AQ17: 20260320 | AV17: 洗滌注意： ※ 首次洗滌時,深色/飽和色系 較易釋出多餘的固色劑, 屬於正常現象。 ※ 深色衣物建議在首次穿著前先下水清洗, 有助釋出多餘染劑，減少掉色或移染, 可降低染色風險。 ※ 深色與淺色衣物請分開洗滌，避免互相染色或產生移染現象。 ※ 穿搭時請避免與淺色衣物、配件、飾品一同搭配使用，以防止因摩擦或潮濕而導致染色。 | AW17: N | AX17: 2號袋、襯紙 | AY17: 表布:嫘縈50%聚酯纖維45%彈性纖維5% 尺寸:S.M.L | BD17: 2611822011210003 | BE17: R260311036 | BF17: B | BG17: 針織 | BH17: =IF(COUNTIF(工作表1!A:A, $C17)>0, "預購款", "非預購款") -> 非預購款
A18: https://airsblobstage.blob.core.windows.net/photo/purchasephoto/SH0192QT.webp | B18: SH | C18: 2611829017 | D18: SH0192QT | E18: 252-0192QT | F18: 20260317 | G18: 0192QT | H18: F | I18: 010 | J18: 深藍 | K18: N | L18: 圓領愛心刺繡短袖排扣開襟麻花針織衫 | M18: 26 | N18: 春 | O18: W10 | P18: 2026-03-02 | S18: 20260331 | T18: OL | U18: 針織 | V18: 短袖針織 | W18: 1280 | X18: 49.99 | Y18: 169 | Z18: 919000 | AA18: 153600 | AB18: 0 | AD18: Outlet追加單 | AE18: 2 | AJ18: 40 | AK18: 40 | AL18: 120 | AM18: 40 | AN18: 0 | AO18: 40 | AP18: Y | AQ18: 20260408 | AV18: 洗滌注意： ※ 首次洗滌時,深色/飽和色系 較易釋出多餘的固色劑, 屬於正常現象。 ※ 深色衣物建議在首次穿著前先下水清洗, 有助釋出多餘染劑，減少掉色或移染, 可降低染色風險。 ※ 深色與淺色衣物請分開洗滌，避免互相染色或產生移染現象。 ※ 穿搭時請避免與淺色衣物、配件、飾品一同搭配使用，以防止因摩擦或潮濕而導致染色。 | AW18: N | AX18: 2號袋、襯紙 | AY18: 主紗:尼龍42%聚酯纖維30%亞克力纖維22%羊毛6% 尺寸:F | BD18: 2611829017010004 | BE18: R260317057 | BF18: B | BG18: 毛織 | BH18: =IF(COUNTIF(工作表1!A:A, $C18)>0, "預購款", "非預購款") -> 非預購款
A19: https://airsblobstage.blob.core.windows.net/photo/purchasephoto/SH0192QT.webp | B19: SH | C19: 2611829017 | D19: SH0192QT | E19: 252-0192QT | F19: 20260317 | G19: 0192QT | H19: F | I19: 035 | J19: 淺灰 | K19: N | L19: 圓領愛心刺繡短袖排扣開襟麻花針織衫 | M19: 26 | N19: 春 | O19: W10 | P19: 2026-03-02 | S19: 20260331 | T19: OL | U19: 針織 | V19: 短袖針織 | W19: 1280 | X19: 49.99 | Y19: 169 | Z19: 919000 | AA19: 153600 | AB19: 0 | AD19: Outlet追加單 | AE19: 2 | AJ19: 80 | AK19: 80 | AL19: 120 | AM19: 80 | AN19: 0 | AO19: 80 | AP19: Y | AQ19: 20260408 | AV19: 洗滌注意： ※ 首次洗滌時,深色/飽和色系 較易釋出多餘的固色劑, 屬於正常現象。 ※ 深色衣物建議在首次穿著前先下水清洗, 有助釋出多餘染劑，減少掉色或移染, 可降低染色風險。 ※ 深色與淺色衣物請分開洗滌，避免互相染色或產生移染現象。 ※ 穿搭時請避免與淺色衣物、配件、飾品一同搭配使用，以防止因摩擦或潮濕而導致染色。 | AW19: N | AX19: 2號袋、襯紙 | AY19: 主紗:尼龍42%聚酯纖維30%亞克力纖維22%羊毛6% 尺寸:F | BD19: 2611829017035004 | BE19: R260317057 | BF19: B | BG19: 毛織 | BH19: =IF(COUNTIF(工作表1!A:A, $C19)>0, "預購款", "非預購款") -> 非預購款
A20: https://airsblobstage.blob.core.windows.net/photo/purchasephoto/SH188 1QT.webp | B20: SH | C20: 2611821026 | D20: SH188-1QT | E20: 252-188-1QT | F20: 20260413 | G20: 188-1QT | H20: F | I20: 002 | J20: 白 | K20: N | L20: 長袖襯衫 | M20: 26 | N20: 春 | O20: W10 | P20: 2026-03-02 | S20: 20260427 | T20: OL | U20: 上衣 | V20: 長袖襯衫 | W20: 1180 | X20: 49.99 | Y20: 155 | Z20: 859000 | AA20: 483800 | AB20: 0 | AD20: Outlet追加單 | AE20: 2 | AJ20: 140 | AK20: 140 | AL20: 410 | AM20: 140 | AN20: 0 | AO20: 140 | AP20: Y | AQ20: 20260506 | AV20: 洗滌注意： ※ 首次洗滌時,深色/飽和色系 較易釋出多餘的固色劑, 屬於正常現象。 ※ 深色衣物建議在首次穿著前先下水清洗, 有助釋出多餘染劑，減少掉色或移染, 可降低染色風險。 ※ 深色與淺色衣物請分開洗滌，避免互相染色或產生移染現象。 ※ 穿搭時請避免與淺色衣物、配件、飾品一同搭配使用，以防止因摩擦或潮濕而導致染色。 | AW20: N | AX20: 2號袋、襯紙、領標*2、洗標*2、成分標*2 | AY20: 表布:棉100% 外件表布:嫘縈50%聚酯纖維28%尼龍22% 尺寸:F | BD20: 2611821026002004 | BE20: R260413004 | BF20: B | BG20: 平織 | BH20: =IF(COUNTIF(工作表1!A:A, $C20)>0, "預購款", "非預購款") -> 非預購款
A21: https://airsblobstage.blob.core.windows.net/photo/purchasephoto/SH188 1QT.webp | B21: SH | C21: 2611821026 | D21: SH188-1QT | E21: 252-188-1QT | F21: 20260413 | G21: 188-1QT | H21: F | I21: 003 | J21: 藍 | K21: N | L21: 長袖襯衫 | M21: 26 | N21: 春 | O21: W10 | P21: 2026-03-02 | S21: 20260427 | T21: OL | U21: 上衣 | V21: 長袖襯衫 | W21: 1180 | X21: 49.99 | Y21: 155 | Z21: 859000 | AA21: 483800 | AB21: 0 | AD21: Outlet追加單 | AE21: 2 | AJ21: 270 | AK21: 270 | AL21: 410 | AM21: 268 | AN21: 0 | AO21: 268 | AP21: Y | AQ21: 20260506 | AV21: 洗滌注意： ※ 首次洗滌時,深色/飽和色系 較易釋出多餘的固色劑, 屬於正常現象。 ※ 深色衣物建議在首次穿著前先下水清洗, 有助釋出多餘染劑，減少掉色或移染, 可降低染色風險。 ※ 深色與淺色衣物請分開洗滌，避免互相染色或產生移染現象。 ※ 穿搭時請避免與淺色衣物、配件、飾品一同搭配使用，以防止因摩擦或潮濕而導致染色。 | AW21: N | AX21: 2號袋、襯紙、領標*2、洗標*2、成分標*2 | AY21: 表布:棉100% 外件表布:嫘縈50%聚酯纖維28%尼龍22% 尺寸:F | BD21: 2611821026003004 | BE21: R260413004 | BF21: B | BG21: 平織 | BH21: =IF(COUNTIF(工作表1!A:A, $C21)>0, "預購款", "非預購款") -> 非預購款
A22: https://airsblobstage.blob.core.windows.net/photo/purchasephoto/SH60037QT.webp | B22: SH | C22: 2611834002 | D22: SH60037QT | E22: 252-60037QT | F22: 20260415 | G22: 60037QT | H22: S | I22: 210 | J22: 深灰 | K22: N | L22: 側開衩短褲裙 | M22: 26 | N22: 春 | O22: W10 | P22: 2026-03-02 | S22: 20260429 | T22: OL | U22: 褲裙 | V22: 短褲 | W22: 1080 | X22: 44.99 | Y22: 139 | Z22: 779000 | AA22: 172800 | AB22: 0 | AD22: Outlet追加單 | AE22: 1 | AJ22: 80 | AK22: 80 | AL22: 160 | AM22: 80 | AN22: 0 | AO22: 80 | AP22: Y | AQ22: 20260506 | AV22: 洗滌注意： ※ 首次洗滌時,深色/飽和色系 較易釋出多餘的固色劑, 屬於正常現象。 ※ 深色衣物建議在首次穿著前先下水清洗, 有助釋出多餘染劑，減少掉色或移染, 可降低染色風險。 ※ 深色與淺色衣物請分開洗滌，避免互相染色或產生移染現象。 ※ 穿搭時請避免與淺色衣物、配件、飾品一同搭配使用，以防止因摩擦或潮濕而導致染色。 | AW22: N | AX22: 2號袋、襯紙 | AY22: 表布:聚酯纖維96%彈性纖維4% 裡布:聚酯纖維100% 尺寸:S.M.L | BD22: 2611834002210001 | BE22: R260415087 | BF22: B | BG22: 平織 | BH22: =IF(COUNTIF(工作表1!A:A, $C22)>0, "預購款", "非預購款") -> 非預購款
A23: https://airsblobstage.blob.core.windows.net/photo/purchasephoto/SH60037QT.webp | B23: SH | C23: 2611834002 | D23: SH60037QT | E23: 252-60037QT | F23: 20260415 | G23: 60037QT | H23: M | I23: 210 | J23: 深灰 | K23: N | L23: 側開衩短褲裙 | M23: 26 | N23: 春 | O23: W10 | P23: 2026-03-02 | S23: 20260429 | T23: OL | U23: 褲裙 | V23: 短褲 | W23: 1080 | X23: 44.99 | Y23: 139 | Z23: 779000 | AA23: 172800 | AB23: 0 | AD23: Outlet追加單 | AE23: 1 | AJ23: 50 | AK23: 50 | AL23: 160 | AM23: 48 | AN23: 0 | AO23: 48 | AP23: Y | AQ23: 20260506 | AV23: 洗滌注意： ※ 首次洗滌時,深色/飽和色系 較易釋出多餘的固色劑, 屬於正常現象。 ※ 深色衣物建議在首次穿著前先下水清洗, 有助釋出多餘染劑，減少掉色或移染, 可降低染色風險。 ※ 深色與淺色衣物請分開洗滌，避免互相染色或產生移染現象。 ※ 穿搭時請避免與淺色衣物、配件、飾品一同搭配使用，以防止因摩擦或潮濕而導致染色。 | AW23: N | AX23: 2號袋、襯紙 | AY23: 表布:聚酯纖維96%彈性纖維4% 裡布:聚酯纖維100% 尺寸:S.M.L | BD23: 2611834002210002 | BE23: R260415087 | BF23: B | BG23: 平織 | BH23: =IF(COUNTIF(工作表1!A:A, $C23)>0, "預購款", "非預購款") -> 非預購款
A24: https://airsblobstage.blob.core.windows.net/photo/purchasephoto/SH60037QT.webp | B24: SH | C24: 2611834002 | D24: SH60037QT | E24: 252-60037QT | F24: 20260415 | G24: 60037QT | H24: L | I24: 210 | J24: 深灰 | K24: N | L24: 側開衩短褲裙 | M24: 26 | N24: 春 | O24: W10 | P24: 2026-03-02 | S24: 20260429 | T24: OL | U24: 褲裙 | V24: 短褲 | W24: 1080 | X24: 44.99 | Y24: 139 | Z24: 779000 | AA24: 172800 | AB24: 0 | AD24: Outlet追加單 | AE24: 1 | AJ24: 30 | AK24: 30 | AL24: 160 | AM24: 29 | AN24: 0 | AO24: 29 | AP24: Y | AQ24: 20260506 | AV24: 洗滌注意： ※ 首次洗滌時,深色/飽和色系 較易釋出多餘的固色劑, 屬於正常現象。 ※ 深色衣物建議在首次穿著前先下水清洗, 有助釋出多餘染劑，減少掉色或移染, 可降低染色風險。 ※ 深色與淺色衣物請分開洗滌，避免互相染色或產生移染現象。 ※ 穿搭時請避免與淺色衣物、配件、飾品一同搭配使用，以防止因摩擦或潮濕而導致染色。 | AW24: N | AX24: 2號袋、襯紙 | AY24: 表布:聚酯纖維96%彈性纖維4% 裡布:聚酯纖維100% 尺寸:S.M.L | BD24: 2611834002210003 | BE24: R260415087 | BF24: B | BG24: 平織 | BH24: =IF(COUNTIF(工作表1!A:A, $C24)>0, "預購款", "非預購款") -> 非預購款
A25: https://airsblobstage.blob.core.windows.net/photo/purchasephoto/SH0192QT.webp | B25: SH | C25: 2611829017 | D25: SH0192QT | E25: 252-0192QT | F25: 20260422 | G25: 0192QT | H25: F | I25: 010 | J25: 深藍 | K25: N | L25: 圓領愛心刺繡短袖排扣開襟麻花針織衫 | M25: 26 | N25: 春 | O25: W10 | P25: 2026-03-02 | S25: 20260506 | T25: OL | U25: 針織 | V25: 短袖針織 | W25: 1280 | X25: 49.99 | Y25: 169 | Z25: 919000 | AA25: 192000 | AB25: 0 | AD25: Outlet追加單 | AE25: 2 | AJ25: 50 | AK25: 50 | AL25: 150 | AM25: 50 | AN25: 0 | AO25: 50 | AP25: Y | AQ25: 20260506 | AV25: 洗滌注意： ※ 首次洗滌時,深色/飽和色系 較易釋出多餘的固色劑, 屬於正常現象。 ※ 深色衣物建議在首次穿著前先下水清洗, 有助釋出多餘染劑，減少掉色或移染, 可降低染色風險。 ※ 深色與淺色衣物請分開洗滌，避免互相染色或產生移染現象。 ※ 穿搭時請避免與淺色衣物、配件、飾品一同搭配使用，以防止因摩擦或潮濕而導致染色。 | AW25: N | AX25: 2號袋、襯紙 | AY25: 主紗:尼龍42%聚酯纖維30%亞克力纖維22%羊毛6% 尺寸:F | BD25: 2611829017010004 | BE25: R260422052 | BF25: B | BG25: 毛織 | BH25: =IF(COUNTIF(工作表1!A:A, $C25)>0, "預購款", "非預購款") -> 非預購款
A26: https://airsblobstage.blob.core.windows.net/photo/purchasephoto/SH0192QT.webp | B26: SH | C26: 2611829017 | D26: SH0192QT | E26: 252-0192QT | F26: 20260422 | G26: 0192QT | H26: F | I26: 035 | J26: 淺灰 | K26: N | L26: 圓領愛心刺繡短袖排扣開襟麻花針織衫 | M26: 26 | N26: 春 | O26: W10 | P26: 2026-03-02 | S26: 20260506 | T26: OL | U26: 針織 | V26: 短袖針織 | W26: 1280 | X26: 49.99 | Y26: 169 | Z26: 919000 | AA26: 192000 | AB26: 0 | AD26: Outlet追加單 | AE26: 2 | AJ26: 100 | AK26: 100 | AL26: 150 | AM26: 100 | AN26: 0 | AO26: 100 | AP26: Y | AQ26: 20260506 | AV26: 洗滌注意： ※ 首次洗滌時,深色/飽和色系 較易釋出多餘的固色劑, 屬於正常現象。 ※ 深色衣物建議在首次穿著前先下水清洗, 有助釋出多餘染劑，減少掉色或移染, 可降低染色風險。 ※ 深色與淺色衣物請分開洗滌，避免互相染色或產生移染現象。 ※ 穿搭時請避免與淺色衣物、配件、飾品一同搭配使用，以防止因摩擦或潮濕而導致染色。 | AW26: N | AX26: 2號袋、襯紙 | AY26: 主紗:尼龍42%聚酯纖維30%亞克力纖維22%羊毛6% 尺寸:F | BD26: 2611829017035004 | BE26: R260422052 | BF26: B | BG26: 毛織 | BH26: =IF(COUNTIF(工作表1!A:A, $C26)>0, "預購款", "非預購款") -> 非預購款
A27: https://airsblobstage.blob.core.windows.net/photo/purchasephoto/SH0192QT.webp | B27: SH | C27: 2611829017 | D27: SH0192QT | E27: 252-0192QT | F27: 20260429 | G27: 0192QT | H27: F | I27: 010 | J27: 深藍 | K27: N | L27: 圓領愛心刺繡短袖排扣開襟麻花針織衫 | M27: 26 | N27: 春 | O27: W10 | P27: 2026-03-02 | S27: 20260513 | T27: OL | U27: 針織 | V27: 短袖針織 | W27: 1280 | X27: 49.99 | Y27: 169 | Z27: 919000 | AA27: 192000 | AB27: 0 | AD27: Outlet追加單 | AE27: 2 | AJ27: 50 | AK27: 50 | AL27: 150 | AM27: 50 | AN27: 0 | AO27: 50 | AP27: Y | AQ27: 20260520 | AV27: 洗滌注意： ※ 首次洗滌時,深色/飽和色系 較易釋出多餘的固色劑, 屬於正常現象。 ※ 深色衣物建議在首次穿著前先下水清洗, 有助釋出多餘染劑，減少掉色或移染, 可降低染色風險。 ※ 深色與淺色衣物請分開洗滌，避免互相染色或產生移染現象。 ※ 穿搭時請避免與淺色衣物、配件、飾品一同搭配使用，以防止因摩擦或潮濕而導致染色。 | AW27: N | AX27: 2號袋、襯紙 | AY27: 主紗:尼龍42%聚酯纖維30%亞克力纖維22%羊毛6% 尺寸:F | BD27: 2611829017010004 | BE27: R260429070 | BF27: B | BG27: 毛織 | BH27: =IF(COUNTIF(工作表1!A:A, $C27)>0, "預購款", "非預購款") -> 非預購款
A28: https://airsblobstage.blob.core.windows.net/photo/purchasephoto/SH0192QT.webp | B28: SH | C28: 2611829017 | D28: SH0192QT | E28: 252-0192QT | F28: 20260429 | G28: 0192QT | H28: F | I28: 035 | J28: 淺灰 | K28: N | L28: 圓領愛心刺繡短袖排扣開襟麻花針織衫 | M28: 26 | N28: 春 | O28: W10 | P28: 2026-03-02 | S28: 20260513 | T28: OL | U28: 針織 | V28: 短袖針織 | W28: 1280 | X28: 49.99 | Y28: 169 | Z28: 919000 | AA28: 192000 | AB28: 0 | AD28: Outlet追加單 | AE28: 2 | AJ28: 100 | AK28: 100 | AL28: 150 | AM28: 100 | AN28: 0 | AO28: 100 | AP28: Y | AQ28: 20260520 | AV28: 洗滌注意： ※ 首次洗滌時,深色/飽和色系 較易釋出多餘的固色劑, 屬於正常現象。 ※ 深色衣物建議在首次穿著前先下水清洗, 有助釋出多餘染劑，減少掉色或移染, 可降低染色風險。 ※ 深色與淺色衣物請分開洗滌，避免互相染色或產生移染現象。 ※ 穿搭時請避免與淺色衣物、配件、飾品一同搭配使用，以防止因摩擦或潮濕而導致染色。 | AW28: N | AX28: 2號袋、襯紙 | AY28: 主紗:尼龍42%聚酯纖維30%亞克力纖維22%羊毛6% 尺寸:F | BD28: 2611829017035004 | BE28: R260429070 | BF28: B | BG28: 毛織 | BH28: =IF(COUNTIF(工作表1!A:A, $C28)>0, "預購款", "非預購款") -> 非預購款
B29: SH | C29: 2611822011 | D29: SH2581QT | E29: 252-2581QT | F29: 20260506 | G29: 2581QT | H29: S | I29: 001 | J29: 黑 | K29: N | L29: 長裙 | M29: 26 | N29: 春 | O29: W10 | P29: 2026-03-02 | S29: 20260513 | T29: OL | U29: 裙子 | V29: 長裙 | W29: 1380 | X29: 54.99 | Y29: 179 | Z29: 989000 | AA29: 124200 | AB29: 0 | AD29: Outlet追加單 | AE29: 1 | AJ29: 45 | AK29: 45 | AL29: 90 | AM29: 50 | AN29: 0 | AO29: 50 | AP29: Y | AQ29: 20260520 | AV29: 洗滌注意： ※ 首次洗滌時,深色/飽和色系 較易釋出多餘的固色劑, 屬於正常現象。 ※ 深色衣物建議在首次穿著前先下水清洗, 有助釋出多餘染劑，減少掉色或移染, 可降低染色風險。 ※ 深色與淺色衣物請分開洗滌，避免互相染色或產生移染現象。 ※ 穿搭時請避免與淺色衣物、配件、飾品一同搭配使用，以防止因摩擦或潮濕而導致染色。 | AW29: N | AX29: 2號袋、襯紙 | AY29: 表布:嫘縈50%聚酯纖維45%彈性纖維5% 尺寸:S.M.L | BD29: 2611822011001001 | BE29: R260506055 | BF29: B | BG29: 針織 | BH29: =IF(COUNTIF(工作表1!A:A, $C29)>0, "預購款", "非預購款") -> 非預購款
B30: SH | C30: 2611822011 | D30: SH2581QT | E30: 252-2581QT | F30: 20260506 | G30: 2581QT | H30: M | I30: 001 | J30: 黑 | K30: N | L30: 長裙 | M30: 26 | N30: 春 | O30: W10 | P30: 2026-03-02 | S30: 20260513 | T30: OL | U30: 裙子 | V30: 長裙 | W30: 1380 | X30: 54.99 | Y30: 179 | Z30: 989000 | AA30: 124200 | AB30: 0 | AD30: Outlet追加單 | AE30: 1 | AJ30: 30 | AK30: 30 | AL30: 90 | AM30: 32 | AN30: 0 | AO30: 32 | AP30: Y | AQ30: 20260520 | AV30: 洗滌注意： ※ 首次洗滌時,深色/飽和色系 較易釋出多餘的固色劑, 屬於正常現象。 ※ 深色衣物建議在首次穿著前先下水清洗, 有助釋出多餘染劑，減少掉色或移染, 可降低染色風險。 ※ 深色與淺色衣物請分開洗滌，避免互相染色或產生移染現象。 ※ 穿搭時請避免與淺色衣物、配件、飾品一同搭配使用，以防止因摩擦或潮濕而導致染色。 | AW30: N | AX30: 2號袋、襯紙 | AY30: 表布:嫘縈50%聚酯纖維45%彈性纖維5% 尺寸:S.M.L | BD30: 2611822011001002 | BE30: R260506055 | BF30: B | BG30: 針織 | BH30: =IF(COUNTIF(工作表1!A:A, $C30)>0, "預購款", "非預購款") -> 非預購款
B31: SH | C31: 2611822011 | D31: SH2581QT | E31: 252-2581QT | F31: 20260506 | G31: 2581QT | H31: L | I31: 001 | J31: 黑 | K31: N | L31: 長裙 | M31: 26 | N31: 春 | O31: W10 | P31: 2026-03-02 | S31: 20260513 | T31: OL | U31: 裙子 | V31: 長裙 | W31: 1380 | X31: 54.99 | Y31: 179 | Z31: 989000 | AA31: 124200 | AB31: 0 | AD31: Outlet追加單 | AE31: 1 | AJ31: 15 | AK31: 15 | AL31: 90 | AM31: 17 | AN31: 0 | AO31: 17 | AP31: Y | AQ31: 20260520 | AV31: 洗滌注意： ※ 首次洗滌時,深色/飽和色系 較易釋出多餘的固色劑, 屬於正常現象。 ※ 深色衣物建議在首次穿著前先下水清洗, 有助釋出多餘染劑，減少掉色或移染, 可降低染色風險。 ※ 深色與淺色衣物請分開洗滌，避免互相染色或產生移染現象。 ※ 穿搭時請避免與淺色衣物、配件、飾品一同搭配使用，以防止因摩擦或潮濕而導致染色。 | AW31: N | AX31: 2號袋、襯紙 | AY31: 表布:嫘縈50%聚酯纖維45%彈性纖維5% 尺寸:S.M.L | BD31: 2611822011001003 | BE31: R260506055 | BF31: B | BG31: 針織 | BH31: =IF(COUNTIF(工作表1!A:A, $C31)>0, "預購款", "非預購款") -> 非預購款
A32: https://airsblobstage.blob.core.windows.net/photo/purchasephoto/SH188 1QT.webp | B32: SH | C32: 2611821026 | D32: SH188-1QT | E32: 252-188-1QT | F32: 20260413 | G32: 188-1QT | H32: F | I32: 003 | J32: 藍 | K32: N | L32: 長袖襯衫 | M32: 26 | N32: 春 | O32: W10 | P32: 2026-03-02 | S32: 20260427 | T32: OL | U32: 上衣 | V32: 長袖襯衫 | W32: 1180 | X32: 49.99 | Y32: 155 | Z32: 859000 | AA32: 2360 | AB32: 0 | AD32: Outlet追加單 | AE32: 1 | AJ32: 2 | AK32: 2 | AL32: 2 | AM32: 2 | AN32: 0 | AO32: 2 | AP32: Y | AQ32: 20260511 | AV32: 洗滌注意： ※ 首次洗滌時,深色/飽和色系 較易釋出多餘的固色劑, 屬於正常現象。 ※ 深色衣物建議在首次穿著前先下水清洗, 有助釋出多餘染劑，減少掉色或移染, 可降低染色風險。 ※ 深色與淺色衣物請分開洗滌，避免互相染色或產生移染現象。 ※ 穿搭時請避免與淺色衣物、配件、飾品一同搭配使用，以防止因摩擦或潮濕而導致染色。 | AW32: N | AX32: 2號袋、襯紙、領標*2、洗標*2、成分標*2 | AY32: 表布:棉100% 外件表布:嫘縈50%聚酯纖維28%尼龍22% 尺寸:F | BD32: 2611821026003004 | BE32: R260511013 | BF32: B | BG32: 平織 | BH32: =IF(COUNTIF(工作表1!A:A, $C32)>0, "預購款", "非預購款") -> 非預購款
A33: https://airsblobstage.blob.core.windows.net/photo/purchasephoto/SH60037QT.webp | B33: SH | C33: 2611834002 | D33: SH60037QT | E33: 252-60037QT | F33: 20260415 | G33: 60037QT | H33: S | I33: 210 | J33: 深灰 | K33: N | L33: 側開衩短褲裙 | M33: 26 | N33: 春 | O33: W10 | P33: 2026-03-02 | S33: 20260429 | T33: OL | U33: 褲裙 | V33: 短褲 | W33: 1080 | X33: 44.99 | Y33: 139 | Z33: 779000 | AA33: 3240 | AB33: 0 | AD33: Outlet追加單 | AE33: 1 | AJ33: 3 | AK33: 3 | AL33: 3 | AM33: 3 | AN33: 0 | AO33: 3 | AP33: Y | AQ33: 20260511 | AV33: 洗滌注意： ※ 首次洗滌時,深色/飽和色系 較易釋出多餘的固色劑, 屬於正常現象。 ※ 深色衣物建議在首次穿著前先下水清洗, 有助釋出多餘染劑，減少掉色或移染, 可降低染色風險。 ※ 深色與淺色衣物請分開洗滌，避免互相染色或產生移染現象。 ※ 穿搭時請避免與淺色衣物、配件、飾品一同搭配使用，以防止因摩擦或潮濕而導致染色。 | AW33: N | AX33: 2號袋、襯紙 | AY33: 表布:聚酯纖維96%彈性纖維4% 裡布:聚酯纖維100% 尺寸:S.M.L | BD33: 2611834002210001 | BE33: R260511014 | BF33: B | BG33: 平織 | BH33: =IF(COUNTIF(工作表1!A:A, $C33)>0, "預購款", "非預購款") -> 非預購款
B34: SH | C34: 2611822011 | D34: SH2581QT | E34: 252-2581QT | F34: 20260506 | G34: 2581QT | H34: M | I34: 001 | J34: 黑 | K34: N | L34: 長裙 | M34: 26 | N34: 春 | O34: W10 | P34: 2026-03-02 | S34: 20260513 | T34: OL | U34: 裙子 | V34: 長裙 | W34: 1380 | X34: 54.99 | Y34: 179 | Z34: 989000 | AA34: 4140 | AB34: 0 | AD34: Outlet追加單 | AE34: 1 | AJ34: 3 | AK34: 3 | AL34: 3 | AM34: 3 | AN34: 0 | AO34: 3 | AP34: Y | AQ34: 20260605 | AV34: 洗滌注意： ※ 首次洗滌時,深色/飽和色系 較易釋出多餘的固色劑, 屬於正常現象。 ※ 深色衣物建議在首次穿著前先下水清洗, 有助釋出多餘染劑，減少掉色或移染, 可降低染色風險。 ※ 深色與淺色衣物請分開洗滌，避免互相染色或產生移染現象。 ※ 穿搭時請避免與淺色衣物、配件、飾品一同搭配使用，以防止因摩擦或潮濕而導致染色。 | AW34: N | AX34: 2號袋、襯紙 | AY34: 表布:嫘縈50%聚酯纖維45%彈性纖維5% 尺寸:S.M.L | BD34: 2611822011001002 | BE34: R260521002 | BF34: B | BG34: 針織 | BH34: =IF(COUNTIF(工作表1!A:A, $C34)>0, "預購款", "非預購款") -> 非預購款
A35: https://airsblobstage.blob.core.windows.net/photo/purchasephoto/SH2507QT.webp | B35: SH | C35: 2621829010 | D35: SH2507QT | E35: 252-2507QT | F35: 20260526 | G35: 2507QT | H35: F | I35: 001 | J35: 黑 | K35: N | M35: 26 | N35: 夏 | O35: W23 | P35: 2026-06-01 | S35: 20260609 | T35: OL | U35: 針織 | V35: 長袖針織 | W35: 890 | X35: 39.99 | Y35: 115 | Z35: 639000 | AA35: 258100 | AB35: 0 | AD35: Outlet追加單 | AE35: 3 | AJ35: 120 | AK35: 120 | AL35: 290 | AM35: 120 | AN35: 0 | AO35: 120 | AP35: Y | AQ35: 20260605 | AV35: OUTLET 靜衣仿 洗滌注意： ※ 首次洗滌時,深色/飽和色系 較易釋出多餘的固色劑, 屬於正常現象。 ※ 深色衣物建議在首次穿著前先下水清洗, 有助釋出多餘染劑，減少掉色或移染, 可降低染色風險。 ※ 深色與淺色衣物請分開洗滌，避免互相染色或產生移染現象。 ※ 穿搭時請避免與淺色衣物、配件、飾品一同搭配使用，以防止因摩擦或潮濕而導致染色。 | AW35: N | AX35: 2號袋、襯紙 | AY35: 主紗:嫘縈81%尼龍19% 尺寸:F | BD35: 2621829010001004 | BE35: R260526094 | BF35: B | BG35: 毛織 | BH35: =IF(COUNTIF(工作表1!A:A, $C35)>0, "預購款", "非預購款") -> 非預購款
A36: https://airsblobstage.blob.core.windows.net/photo/purchasephoto/SH2507QT.webp | B36: SH | C36: 2621829010 | D36: SH2507QT | E36: 252-2507QT | F36: 20260526 | G36: 2507QT | H36: F | I36: 002 | J36: 白 | K36: N | M36: 26 | N36: 夏 | O36: W23 | P36: 2026-06-01 | S36: 20260609 | T36: OL | U36: 針織 | V36: 長袖針織 | W36: 890 | X36: 39.99 | Y36: 115 | Z36: 639000 | AA36: 258100 | AB36: 0 | AD36: Outlet追加單 | AE36: 3 | AJ36: 100 | AK36: 100 | AL36: 290 | AM36: 100 | AN36: 0 | AO36: 100 | AP36: Y | AQ36: 20260605 | AV36: OUTLET 靜衣仿 洗滌注意： ※ 首次洗滌時,深色/飽和色系 較易釋出多餘的固色劑, 屬於正常現象。 ※ 深色衣物建議在首次穿著前先下水清洗, 有助釋出多餘染劑，減少掉色或移染, 可降低染色風險。 ※ 深色與淺色衣物請分開洗滌，避免互相染色或產生移染現象。 ※ 穿搭時請避免與淺色衣物、配件、飾品一同搭配使用，以防止因摩擦或潮濕而導致染色。 | AW36: N | AX36: 2號袋、襯紙 | AY36: 主紗:嫘縈81%尼龍19% 尺寸:F | BD36: 2621829010002004 | BE36: R260526094 | BF36: B | BG36: 毛織 | BH36: =IF(COUNTIF(工作表1!A:A, $C36)>0, "預購款", "非預購款") -> 非預購款
A37: https://airsblobstage.blob.core.windows.net/photo/purchasephoto/SH2507QT.webp | B37: SH | C37: 2621829010 | D37: SH2507QT | E37: 252-2507QT | F37: 20260526 | G37: 2507QT | H37: F | I37: 003 | J37: 藍 | K37: N | M37: 26 | N37: 夏 | O37: W23 | P37: 2026-06-01 | S37: 20260609 | T37: OL | U37: 針織 | V37: 長袖針織 | W37: 890 | X37: 39.99 | Y37: 115 | Z37: 639000 | AA37: 258100 | AB37: 0 | AD37: Outlet追加單 | AE37: 3 | AJ37: 70 | AK37: 70 | AL37: 290 | AM37: 70 | AN37: 0 | AO37: 70 | AP37: Y | AQ37: 20260605 | AV37: OUTLET 靜衣仿 洗滌注意： ※ 首次洗滌時,深色/飽和色系 較易釋出多餘的固色劑, 屬於正常現象。 ※ 深色衣物建議在首次穿著前先下水清洗, 有助釋出多餘染劑，減少掉色或移染, 可降低染色風險。 ※ 深色與淺色衣物請分開洗滌，避免互相染色或產生移染現象。 ※ 穿搭時請避免與淺色衣物、配件、飾品一同搭配使用，以防止因摩擦或潮濕而導致染色。 | AW37: N | AX37: 2號袋、襯紙 | AY37: 主紗:嫘縈81%尼龍19% 尺寸:F | BD37: 2621829010003004 | BE37: R260526094 | BF37: B | BG37: 毛織 | BH37: =IF(COUNTIF(工作表1!A:A, $C37)>0, "預購款", "非預購款") -> 非預購款
A38: https://airsblobstage.blob.core.windows.net/photo/purchasephoto/SH2510QT.webp | B38: SH | C38: 2621821067 | D38: SH2510QT | E38: 252-2510QT | F38: 20260526 | G38: 2510QT | H38: F | I38: 017 | J38: 咖啡 | K38: N | M38: 26 | N38: 夏 | O38: W23 | P38: 2026-06-01 | S38: 20260609 | T38: OL | U38: 上衣 | V38: 短版挖肩上衣 | W38: 790 | X38: 34.99 | Y38: 99 | Z38: 569000 | AA38: 79000 | AB38: 0 | AD38: Outlet追加單 | AE38: 1 | AJ38: 100 | AK38: 100 | AL38: 100 | AM38: 0 | AN38: 0 | AO38: 0 | AP38: N | AV38: OUTLET 小熊衣櫃 洗滌注意： ※ 首次洗滌時,深色/飽和色系 較易釋出多餘的固色劑, 屬於正常現象。 ※ 深色衣物建議在首次穿著前先下水清洗, 有助釋出多餘染劑，減少掉色或移染, 可降低染色風險。 ※ 深色與淺色衣物請分開洗滌，避免互相染色或產生移染現象。 ※ 穿搭時請避免與淺色衣物、配件、飾品一同搭配使用，以防止因摩擦或潮濕而導致染色。 | AW38: N | AX38: 2號袋、襯紙、胸殼 | AY38: 表布:嫘縈93%彈性纖維7% 罩杯內層材質:聚酯纖維100% 尺寸:F | BD38: 2621821067017004 | BE38: R260526095 | BF38: B | BG38: 針織 | BH38: =IF(COUNTIF(工作表1!A:A, $C38)>0, "預購款", "非預購款") -> 非預購款
A39: https://airsblobstage.blob.core.windows.net/photo/purchasephoto/SH0192QT.webp | B39: SH | C39: 2611829017 | D39: SH0192QT | E39: 252-0192QT | F39: 20260603 | G39: 0192QT | H39: F | I39: 010 | J39: 深藍 | K39: N | L39: 圓領愛心刺繡短袖排扣開襟麻花針織衫 | M39: 26 | N39: 春 | O39: W10 | P39: 2026-03-02 | S39: 20260617 | T39: OL | U39: 針織 | V39: 短袖針織 | W39: 1280 | X39: 49.99 | Y39: 169 | Z39: 919000 | AA39: 204800 | AB39: 0 | AD39: Outlet追加單 | AE39: 2 | AJ39: 60 | AK39: 60 | AL39: 160 | AM39: 0 | AN39: 0 | AO39: 0 | AP39: N | AV39: 洗滌注意： ※ 首次洗滌時,深色/飽和色系 較易釋出多餘的固色劑, 屬於正常現象。 ※ 深色衣物建議在首次穿著前先下水清洗, 有助釋出多餘染劑，減少掉色或移染, 可降低染色風險。 ※ 深色與淺色衣物請分開洗滌，避免互相染色或產生移染現象。 ※ 穿搭時請避免與淺色衣物、配件、飾品一同搭配使用，以防止因摩擦或潮濕而導致染色。 | AW39: N | AX39: 2號袋、襯紙 | AY39: 主紗:尼龍42%聚酯纖維30%亞克力纖維22%羊毛6% 尺寸:F | BD39: 2611829017010004 | BE39: R260603090 | BF39: B | BG39: 毛織 | BH39: =IF(COUNTIF(工作表1!A:A, $C39)>0, "預購款", "非預購款") -> 非預購款
A40: https://airsblobstage.blob.core.windows.net/photo/purchasephoto/SH0192QT.webp | B40: SH | C40: 2611829017 | D40: SH0192QT | E40: 252-0192QT | F40: 20260603 | G40: 0192QT | H40: F | I40: 035 | J40: 淺灰 | K40: N | L40: 圓領愛心刺繡短袖排扣開襟麻花針織衫 | M40: 26 | N40: 春 | O40: W10 | P40: 2026-03-02 | S40: 20260617 | T40: OL | U40: 針織 | V40: 短袖針織 | W40: 1280 | X40: 49.99 | Y40: 169 | Z40: 919000 | AA40: 204800 | AB40: 0 | AD40: Outlet追加單 | AE40: 2 | AJ40: 100 | AK40: 100 | AL40: 160 | AM40: 0 | AN40: 0 | AO40: 0 | AP40: N | AV40: 洗滌注意： ※ 首次洗滌時,深色/飽和色系 較易釋出多餘的固色劑, 屬於正常現象。 ※ 深色衣物建議在首次穿著前先下水清洗, 有助釋出多餘染劑，減少掉色或移染, 可降低染色風險。 ※ 深色與淺色衣物請分開洗滌，避免互相染色或產生移染現象。 ※ 穿搭時請避免與淺色衣物、配件、飾品一同搭配使用，以防止因摩擦或潮濕而導致染色。 | AW40: N | AX40: 2號袋、襯紙 | AY40: 主紗:尼龍42%聚酯纖維30%亞克力纖維22%羊毛6% 尺寸:F | BD40: 2611829017035004 | BE40: R260603090 | BF40: B | BG40: 毛織 | BH40: =IF(COUNTIF(工作表1!A:A, $C40)>0, "預購款", "非預購款") -> 非預購款
...

Sheet 工作表1
A1: 商品編號 | B1: 款號
A2: 2621821011 | B2: XY62742Q
A3: 2621823005 | B3: XY62743Q
A4: 2620823002 | B4: XY62743QF
A5: 2621825002 | B5: SHY2601QC
A6: 2620121009 | B6: EB19694
A7: 2620821010 | B7: EB19694F
A8: 2620121008 | B8: EB19919
A9: 2620129003 | B9: GE00716
A10: 2620122002 | B10: XY62810
A11: 2620822002 | B11: XY62810F
A12: 2610125007 | B12: XY818C
... A24: 2620125005 | B24: SHY1014C
